INFO 2022-09-12 07:41:24,628 - Start time: 20220912T074124
WARNING 2022-09-12 07:41:38,222 - Exception encountered in fetch_trial_data. Traceback: Traceback (most recent call last):
  File "/global/cscratch1/sd/yazbeck/boa/boa/metaclasses.py", line 19, in wrapper
    return func(*args, **kwargs)
  File "/global/cscratch1/sd/yazbeck/boa/boa/wrapper_utils.py", line 52, in wrapper
    return func(*args, **kwargs)
  File "/global/cscratch1/sd/yazbeck/US_LA3_Wetl_C3Gra_Trans/elm_wrapper.py", line 433, in fetch_trial_data
    y_pred, y_true = get_model_obs(
  File "/global/cscratch1/sd/yazbeck/US_LA3_Wetl_C3Gra_Trans/elm_wrapper.py", line 297, in get_model_obs
    obsdf = obsdf.loc[modeldf.Time[0] : modeldf["Time"].iloc[-1]]
  File "/global/homes/y/yazbeck/.conda/envs/boa_env_cori/lib/python3.9/site-packages/pandas/core/generic.py", line 5575, in __getattr__
    return object.__getattribute__(self, name)
AttributeError: 'DataFrame' object has no attribute 'Time'

